Workbook

Sheet Dossier_Projet
A1: Projet MOTK Habitat - colonne vertébrale de l'écosystème LTS
A2: Document lisible par tous : logique métier, rôle des onglets, et articulation Excel -> generate_contacts.js -> server.js -> App React
A4: 1. Objet du système
A5: Le classeur devient la base de référence du parc LTS. Une ligne de logement = un code_acces stable. Les feuilles métier structurent la gestion locative, les ventes, les travaux, les entreprises et les contacts Telegram.
A7: 2. Rôle des onglets
A8: LTS_Parc = référentiel du patrimoine ; Contacts_Activation = personnes et activation Telegram ; Gestion_Locative = dossier courant du locataire ; Ventes = parcours d'accession ; Travaux = demandes et interventions ; Marches / Entreprises_Activation = pilotage prestataires ; Notifications / Historique_Actions = traçabilité ; Pilotage = indicateurs.
A10: 3. Generate_contacts.js
A11: Le script prépare les activations : normalise les téléphones, génère les codes secrets, construit les liens Telegram et prépare les messages d'activation à envoyer aux habitants.
A13: 4. Server.js
A14: Le serveur lit les feuilles Excel, contrôle la cohérence, calcule les alertes et les priorités, gère l'activation Telegram, oriente les demandes, puis journalise les notifications envoyées aux locataires et aux entreprises.
A16: 5. Application React
A17: L'application affiche les LTS, les statuts, les alertes, les ventes, les travaux, les entreprises et les indicateurs de pilotage dans une interface simple pour les agents et la direction.
... A23: Le classeur utilise des référentiels, des listes déroulantes, des colonnes de workflow et des colonnes de calcul. Les agents choisissent, valident, datent et commentent ; les calculs, les blocages et les messages sont automatisés.

Sheet Architecture_Technique
A1: Architecture technique et fonctionnelle
A2: Vue simple du système MOTK Habitat
A3: Composant | B3: Entrées | C3: Traitements | D3: Sorties | E3: Usage
A4: Excel / LTS_Parc | B4: Codes résidence et logement, adresse, vendabilité, diagnostics | C4: Structure de base du patrimoine | D4: Référentiel propre | E4: Base unique de vérité
A5: Contacts_Activation | B5: Noms, téléphones, liens Telegram, code secret | C5: Activation sécurisée, gestion du contact actif | D5: Chat ID, statut d'activation, message d'activation | E5: Relation habitant
A6: Gestion_Locative | B6: Assurance, avis d'impôt, pièce manquante, bail | C6: Contrôle administratif et relances | D6: Alerte gestion, statut dossier | E6: Suivi locatif
A7: Travaux | B7: Demandes, validation agent, attribution entreprise | C7: Workflow demande -> validation -> intervention | D7: Notifications locataire et entreprise | E7: Exécution terrain
A8: Ventes | B8: Demande achat, prix, TAE, SPANC, chèques, notaire | C8: Workflow accession et blocages | D8: Suivi vente, notifications, reste à charge | E8: Pilotage accession
A9: Marches / Entreprises | B9: Marchés, lots, entreprise, mode d'attribution | C9: Orientation vers prestataire marché / hors marché | D9: Activation entreprise et traçabilité | E9: Pilotage prestataires
A10: generate_contacts.js | B10: Contacts_Activation | C10: Normalisation téléphone, code secret, lien Telegram, message | D10: Feuille prête pour campagne d'activation | E10: Préparation opérationnelle
A11: server.js | B11: Toutes les feuilles métiers | C11: Lecture, synchronisation, contrôle, alertes, envoi Telegram | D11: Notifications, historique, dashboard API | E11: Moteur central
A12: App React | B12: API serveur / feuilles consolidées | C12: Visualisation cartographique et métier | D12: Vues agents / direction | E12: Pilotage et supervision

Sheet Parametres
A1: Paramètres du système
A2: Valeurs de base à ajuster avant déploiement
A3: Paramètre | B3: Valeur | C3: Commentaire | D3: Catégorie | E3: Résidences non vendables
A4: TELEGRAM_BOT_USERNAME | B4: motk_notification_bot | C4: Nom du bot Telegram utilisé pour les liens d'activation | D4: Technique | E4: ALAMANDAS
A5: CHEQUE_PRIMO_MIN | B5: 500 | C5: Montant minimal chèque primo-accédant | D5: Vente | E5: SAPOTIS
A6: CHEQUE_PRIMO_MAX | B6: 5000 | C6: Montant maximal chèque primo-accédant | D6: Vente | E6: GRENADINES
A7: CHEQUE_CINOR | B7: 3000 | C7: Montant fixe aide CINOR | D7: Vente | E7: CLOTILDA
A8: TAE_PAR_DEFAUT_VENTE | B8: oui | C8: Tout logement en vente doit avoir un diag TAE | D8: Vente
A9: SPANC_PAR_DEFAUT | B9: non | C9: Par défaut : ajuster logement par logement | D9: Vente
A10: DELAI_RELANCE_JOURS | B10: 7 | C10: Délai conseillé pour relance automatique | D10: Pilotage
A11: TELEGRAM_POLL_INTERVAL_MS | B11: 5000 | C11: Poll Telegram côté serveur | D11: Technique
A12: CHECK_INTERVAL_MS | B12: 90000 | C12: Scan périodique du moteur d'alertes | D12: Technique

Sheet Contacts_Activation
A1: secteur | B1: quartier | C1: code_lts | D1: code_acces | E1: nom_lts | F1: nom | G1: prenom | H1: telephone_principal | I1: telephone_secondaire | J1: telephone_normalise | K1: remarques_contact | L1: email | M1: type_contact | N1: contact_actif | O1: date_entree | P1: date_sortie | Q1: motif_sortie | R1: telegram_chat_id | S1: statut_activation | T1: date_activation | U1: code_secret | V1: secret_utilise | W1: tentatives_activation | X1: activation_bloquee | Y1: motif_blocage | Z1: date_derniere_tentative | AA1: activation_etape | AB1: activation_code_temp | AC1: lien_telegram_start | AD1: message_activation
A2: 1 | B2: Sainte Cloitlde | C2: LTS-001 | D2: LTS-001-001 | E2: ALAMANDAS | F2: RIVIERE | G2: Fabienne | H2: 0692670367 | J2: 0692670367 | M2: locataire | N2: oui | S2: A activer | U2: 1001 | V2: non | W2: 0 | X2: non | AC2: https://t.me/motk_notification_bot?start=LTS-001-001 | AD2: 🏛️ Ville de Saint-Denis Service Habitat – Projet MOTK Bonjour Fabienne RIVIERE Activez vos notifications logement : Lien : https://t.me/motk_notification_bot?start=LTS-001-001 Code secret : 1001 Étapes : 1) Cliquez sur le lien 2) Appuyez sur Start 3) Envoyez votre numéro de téléphone 4) Envoyez votre code secret.
A3: 1 | B3: Sainte Cloitlde | C3: LTS-001 | D3: LTS-001-002 | E3: ALAMANDAS | F3: ARAYE | G3: Evelyne | H3: 0262294396 | I3: 0692085376 | J3: 0262294396 | M3: locataire | N3: oui | S3: A activer | U3: 1002 | V3: non | W3: 0 | X3: non | AC3: https://t.me/motk_notification_bot?start=LTS-001-002 | AD3: 🏛️ Ville de Saint-Denis Service Habitat – Projet MOTK Bonjour Evelyne ARAYE Activez vos notifications logement : Lien : https://t.me/motk_notification_bot?start=LTS-001-002 Code secret : 1002 Étapes : 1) Cliquez sur le lien 2) Appuyez sur Start 3) Envoyez votre numéro de téléphone 4) Envoyez votre code secret.
A4: 1 | B4: Sainte Cloitlde | C4: LTS-001 | D4: LTS-001-003 | E4: ALAMANDAS | F4: ARLANDON | G4: Jean Luc | H4: 0692253329 | I4: 0692373955 | J4: 0692253329 | K4: FREDERICK ARLANDON | M4: locataire | N4: oui | S4: A activer | U4: 1003 | V4: non | W4: 0 | X4: non | AC4: https://t.me/motk_notification_bot?start=LTS-001-003 | AD4: 🏛️ Ville de Saint-Denis Service Habitat – Projet MOTK Bonjour Jean Luc ARLANDON Activez vos notifications logement : Lien : https://t.me/motk_notification_bot?start=LTS-001-003 Code secret : 1003 Étapes : 1) Cliquez sur le lien 2) Appuyez sur Start 3) Envoyez votre numéro de téléphone 4) Envoyez votre code secret.
A5: 1 | B5: Sainte Cloitlde | C5: LTS-001 | D5: LTS-001-004 | E5: ALAMANDAS | F5: CAZAMBO | G5: Jean François | H5: 0693137209 | J5: 0693137209 | M5: locataire | N5: oui | S5: A activer | U5: 1004 | V5: non | W5: 0 | X5: non | AC5: https://t.me/motk_notification_bot?start=LTS-001-004 | AD5: 🏛️ Ville de Saint-Denis Service Habitat – Projet MOTK Bonjour Jean François CAZAMBO Activez vos notifications logement : Lien : https://t.me/motk_notification_bot?start=LTS-001-004 Code secret : 1004 Étapes : 1) Cliquez sur le lien 2) Appuyez sur Start 3) Envoyez votre numéro de téléphone 4) Envoyez votre code secret.
A6: 1 | B6: Sainte Cloitlde | C6: LTS-001 | D6: LTS-001-005 | E6: ALAMANDAS | F6: CHANE LAW | G6: Jimmy | H6: 0692957824 | J6: 0692957824 | M6: locataire | N6: oui | S6: A activer | U6: 1005 | V6: non | W6: 0 | X6: non | AC6: https://t.me/motk_notification_bot?start=LTS-001-005 | AD6: 🏛️ Ville de Saint-Denis Service Habitat – Projet MOTK Bonjour Jimmy CHANE LAW Activez vos notifications logement : Lien : https://t.me/motk_notification_bot?start=LTS-001-005 Code secret : 1005 Étapes : 1) Cliquez sur le lien 2) Appuyez sur Start 3) Envoyez votre numéro de téléphone 4) Envoyez votre code secret.
A7: 1 | B7: Sainte Cloitlde | C7: LTS-001 | D7: LTS-001-006 | E7: ALAMANDAS | F7: METELLUS | G7: Stéphane | H7: 0693044649 | J7: 0693044649 | M7: locataire | N7: oui | S7: A activer | U7: 1006 | V7: non | W7: 0 | X7: non | AC7: https://t.me/motk_notification_bot?start=LTS-001-006 | AD7: 🏛️ Ville de Saint-Denis Service Habitat – Projet MOTK Bonjour Stéphane METELLUS Activez vos notifications logement : Lien : https://t.me/motk_notification_bot?start=LTS-001-006 Code secret : 1006 Étapes : 1) Cliquez sur le lien 2) Appuyez sur Start 3) Envoyez votre numéro de téléphone 4) Envoyez votre code secret.
A8: 1 | B8: Sainte Cloitlde | C8: LTS-001 | D8: LTS-001-007 | E8: ALAMANDAS | F8: FICHORA | G8: Armand | H8: 0262284589 | J8: 0262284589 | M8: locataire | N8: oui | S8: A activer | U8: 1007 | V8: non | W8: 0 | X8: non | AC8: https://t.me/motk_notification_bot?start=LTS-001-007 | AD8: 🏛️ Ville de Saint-Denis Service Habitat – Projet MOTK Bonjour Armand FICHORA Activez vos notifications logement : Lien : https://t.me/motk_notification_bot?start=LTS-001-007 Code secret : 1007 Étapes : 1) Cliquez sur le lien 2) Appuyez sur Start 3) Envoyez votre numéro de téléphone 4) Envoyez votre code secret.
A9: 1 | B9: Sainte Cloitlde | C9: LTS-001 | D9: LTS-001-008 | E9: ALAMANDAS | F9: LOUISE | G9: Marie | H9: 0693051870 | J9: 0693051870 | K9: emmanuelle Boyer | M9: locataire | N9: oui | S9: A activer | U9: 1008 | V9: non | W9: 0 | X9: non | AC9: https://t.me/motk_notification_bot?start=LTS-001-008 | AD9: 🏛️ Ville de Saint-Denis Service Habitat – Projet MOTK Bonjour Marie LOUISE Activez vos notifications logement : Lien : https://t.me/motk_notification_bot?start=LTS-001-008 Code secret : 1008 Étapes : 1) Cliquez sur le lien 2) Appuyez sur Start 3) Envoyez votre numéro de téléphone 4) Envoyez votre code secret.
A10: 1 | B10: Sainte Cloitlde | C10: LTS-001 | D10: LTS-001-009 | E10: ALAMANDAS | F10: GALTIER | G10: Rita Marie | H10: 0262293081 | I10: 0692898654 | J10: 0262293081 | K10: fils | M10: locataire | N10: oui | S10: A activer | U10: 1009 | V10: non | W10: 0 | X10: non | AC10: https://t.me/motk_notification_bot?start=LTS-001-009 | AD10: 🏛️ Ville de Saint-Denis Service Habitat – Projet MOTK Bonjour Rita Marie GALTIER Activez vos notifications logement : Lien : https://t.me/motk_notification_bot?start=LTS-001-009 Code secret : 1009 Étapes : 1) Cliquez sur le lien 2) Appuyez sur Start 3) Envoyez votre numéro de téléphone 4) Envoyez votre code secret.
A11: 1 | B11: Sainte Cloitlde | C11: LTS-001 | D11: LTS-001-010 | E11: ALAMANDAS | F11: GERVILLE | G11: Rose May | H11: 0692464983 | J11: 0692464983 | M11: locataire | N11: oui | S11: A activer | U11: 1010 | V11: non | W11: 0 | X11: non | AC11: https://t.me/motk_notification_bot?start=LTS-001-010 | AD11: 🏛️ Ville de Saint-Denis Service Habitat – Projet MOTK Bonjour Rose May GERVILLE Activez vos notifications logement : Lien : https://t.me/motk_notification_bot?start=LTS-001-010 Code secret : 1010 Étapes : 1) Cliquez sur le lien 2) Appuyez sur Start 3) Envoyez votre numéro de téléphone 4) Envoyez votre code secret.
A12: 1 | B12: Sainte Cloitlde | C12: LTS-001 | D12: LTS-001-011 | E12: ALAMANDAS | F12: GRENIER | G12: Ruffine Marie | H12: 0262503633 | I12: 0692190983 | J12: 0262503633 | K12: OU | M12: locataire | N12: oui | S12: A activer | U12: 1011 | V12: non | W12: 0 | X12: non | AC12: https://t.me/motk_notification_bot?start=LTS-001-011 | AD12: 🏛️ Ville de Saint-Denis Service Habitat – Projet MOTK Bonjour Ruffine Marie GRENIER Activez vos notifications logement : Lien : https://t.me/motk_notification_bot?start=LTS-001-011 Code secret : 1011 Étapes : 1) Cliquez sur le lien 2) Appuyez sur Start 3) Envoyez votre numéro de téléphone 4) Envoyez votre code secret.
A13: 1 | B13: Sainte Cloitlde | C13: LTS-001 | D13: LTS-001-012 | E13: ALAMANDAS | F13: SAUTRON | G13: Willy David | H13: 0693634302 | I13: 0692084218 / 0692494271 | J13: 0693634302 | K13: Mme SAUTRON | M13: locataire | N13: oui | S13: A activer | U13: 1012 | V13: non | W13: 0 | X13: non | AC13: https://t.me/motk_notification_bot?start=LTS-001-012 | AD13: 🏛️ Ville de Saint-Denis Service Habitat – Projet MOTK Bonjour Willy David SAUTRON Activez vos notifications logement : Lien : https://t.me/motk_notification_bot?start=LTS-001-012 Code secret : 1012 Étapes : 1) Cliquez sur le lien 2) Appuyez sur Start 3) Envoyez votre numéro de téléphone 4) Envoyez votre code secret.
A14: 1 | B14: Sainte Cloitlde | C14: LTS-001 | D14: LTS-001-013 | E14: ALAMANDAS | F14: LAFABLE | G14: Philippe | H14: 0692467006 | J14: 0692467006 | M14: locataire | N14: oui | S14: A activer | U14: 1013 | V14: non | W14: 0 | X14: non | AC14: https://t.me/motk_notification_bot?start=LTS-001-013 | AD14: 🏛️ Ville de Saint-Denis Service Habitat – Projet MOTK Bonjour Philippe LAFABLE Activez vos notifications logement : Lien : https://t.me/motk_notification_bot?start=LTS-001-013 Code secret : 1013 Étapes : 1) Cliquez sur le lien 2) Appuyez sur Start 3) Envoyez votre numéro de téléphone 4) Envoyez votre code secret.
A15: 1 | B15: Sainte Cloitlde | C15: LTS-001 | D15: LTS-001-014 | E15: ALAMANDAS | F15: LAURENT | G15: Jean René | H15: 0262289120 | J15: 0262289120 | M15: locataire | N15: oui | S15: A activer | U15: 1014 | V15: non | W15: 0 | X15: non | AC15: https://t.me/motk_notification_bot?start=LTS-001-014 | AD15: 🏛️ Ville de Saint-Denis Service Habitat – Projet MOTK Bonjour Jean René LAURENT Activez vos notifications logement : Lien : https://t.me/motk_notification_bot?start=LTS-001-014 Code secret : 1014 Étapes : 1) Cliquez sur le lien 2) Appuyez sur Start 3) Envoyez votre numéro de téléphone 4) Envoyez votre code secret.
A16: 1 | B16: Sainte Cloitlde | C16: LTS-001 | D16: LTS-001-015 | E16: ALAMANDAS | F16: LAURENT | G16: Jean Bernard | H16: 0692916258 | J16: 0692916258 | M16: locataire | N16: oui | S16: A activer | U16: 1015 | V16: non | W16: 0 | X16: non | AC16: https://t.me/motk_notification_bot?start=LTS-001-015 | AD16: 🏛️ Ville de Saint-Denis Service Habitat – Projet MOTK Bonjour Jean Bernard LAURENT Activez vos notifications logement : Lien : https://t.me/motk_notification_bot?start=LTS-001-015 Code secret : 1015 Étapes : 1) Cliquez sur le lien 2) Appuyez sur Start 3) Envoyez votre numéro de téléphone 4) Envoyez votre code secret.
A17: 1 | B17: Sainte Cloitlde | C17: LTS-001 | D17: LTS-001-016 | E17: ALAMANDAS | F17: MARKA | G17: Claude | H17: 0692906779 | J17: 0692906779 | M17: locataire | N17: oui | S17: A activer | U17: 1016 | V17: non | W17: 0 | X17: non | AC17: https://t.me/motk_notification_bot?start=LTS-001-016 | AD17: 🏛️ Ville de Saint-Denis Service Habitat – Projet MOTK Bonjour Claude MARKA Activez vos notifications logement : Lien : https://t.me/motk_notification_bot?start=LTS-001-016 Code secret : 1016 Étapes : 1) Cliquez sur le lien 2) Appuyez sur Start 3) Envoyez votre numéro de téléphone 4) Envoyez votre code secret.
A18: 1 | B18: Sainte Cloitlde | C18: LTS-001 | D18: LTS-001-017 | E18: ALAMANDAS | F18: MOUTOUSSAMY | G18: Jacques Antoine | H18: 0692807626 | I18: 0262190122 | J18: 0692807626 | M18: locataire | N18: oui | S18: A activer | U18: 1017 | V18: non | W18: 0 | X18: non | AC18: https://t.me/motk_notification_bot?start=LTS-001-017 | AD18: 🏛️ Ville de Saint-Denis Service Habitat – Projet MOTK Bonjour Jacques Antoine MOUTOUSSAMY Activez vos notifications logement : Lien : https://t.me/motk_notification_bot?start=LTS-001-017 Code secret : 1017 Étapes : 1) Cliquez sur le lien 2) Appuyez sur Start 3) Envoyez votre numéro de téléphone 4) Envoyez votre code secret.
A19: 1 | B19: Sainte Cloitlde | C19: LTS-001 | D19: LTS-001-018 | E19: ALAMANDAS | F19: PAYET | G19: Josiane Aline | H19: 0262504956 | I19: 0692677087 | J19: 0262504956 | M19: locataire | N19: oui | S19: A activer | U19: 1018 | V19: non | W19: 0 | X19: non | AC19: https://t.me/motk_notification_bot?start=LTS-001-018 | AD19: 🏛️ Ville de Saint-Denis Service Habitat – Projet MOTK Bonjour Josiane Aline PAYET Activez vos notifications logement : Lien : https://t.me/motk_notification_bot?start=LTS-001-018 Code secret : 1018 Étapes : 1) Cliquez sur le lien 2) Appuyez sur Start 3) Envoyez votre numéro de téléphone 4) Envoyez votre code secret.
A20: 1 | B20: Sainte Cloitlde | C20: LTS-001 | D20: LTS-001-019 | E20: ALAMANDAS | F20: ROBERT | G20: Jean Patrick | H20: 0692668371 | I20: 0692916112 | J20: 0692668371 | M20: locataire | N20: oui | S20: A activer | U20: 1019 | V20: non | W20: 0 | X20: non | AC20: https://t.me/motk_notification_bot?start=LTS-001-019 | AD20: 🏛️ Ville de Saint-Denis Service Habitat – Projet MOTK Bonjour Jean Patrick ROBERT Activez vos notifications logement : Lien : https://t.me/motk_notification_bot?start=LTS-001-019 Code secret : 1019 Étapes : 1) Cliquez sur le lien 2) Appuyez sur Start 3) Envoyez votre numéro de téléphone 4) Envoyez votre code secret.
A21: 1 | B21: Sainte Cloitlde | C21: LTS-001 | D21: LTS-001-020 | E21: ALAMANDAS | F21: REFANE | G21: Marie Virginie | H21: 0692860902 | J21: 0692860902 | M21: locataire | N21: oui | S21: A activer | U21: 1020 | V21: non | W21: 0 | X21: non | AC21: https://t.me/motk_notification_bot?start=LTS-001-020 | AD21: 🏛️ Ville de Saint-Denis Service Habitat – Projet MOTK Bonjour Marie Virginie REFANE Activez vos notifications logement : Lien : https://t.me/motk_notification_bot?start=LTS-001-020 Code secret : 1020 Étapes : 1) Cliquez sur le lien 2) Appuyez sur Start 3) Envoyez votre numéro de téléphone 4) Envoyez votre code secret.
A22: 1 | B22: Sainte Cloitlde | C22: LTS-001 | D22: LTS-001-021 | E22: ALAMANDAS | F22: SINAPAYEN SINAMALE | G22: Henriette | H22: 0693860123 | I22: 0692143045 | J22: 0693860123 | K22: petit fils | M22: locataire | N22: oui | S22: A activer | U22: 1021 | V22: non | W22: 0 | X22: non | AC22: https://t.me/motk_notification_bot?start=LTS-001-021 | AD22: 🏛️ Ville de Saint-Denis Service Habitat – Projet MOTK Bonjour Henriette SINAPAYEN SINAMALE Activez vos notifications logement : Lien : https://t.me/motk_notification_bot?start=LTS-001-021 Code secret : 1021 Étapes : 1) Cliquez sur le lien 2) Appuyez sur Start 3) Envoyez votre numéro de téléphone 4) Envoyez votre code secret.
A23: 1 | B23: Sainte Cloitlde | C23: LTS-001 | D23: LTS-001-022 | E23: ALAMANDAS | F23: MARKA | G23: GREGORY | H23: 0692843883 | J23: 0692843883 | M23: locataire | N23: oui | S23: A activer | U23: 1022 | V23: non | W23: 0 | X23: non | AC23: https://t.me/motk_notification_bot?start=LTS-001-022 | AD23: 🏛️ Ville de Saint-Denis Service Habitat – Projet MOTK Bonjour GREGORY MARKA Activez vos notifications logement : Lien : https://t.me/motk_notification_bot?start=LTS-001-022 Code secret : 1022 Étapes : 1) Cliquez sur le lien 2) Appuyez sur Start 3) Envoyez votre numéro de téléphone 4) Envoyez votre code secret.
A24: 1 | B24: Sainte Cloitlde | C24: LTS-001 | D24: LTS-001-023 | E24: ALAMANDAS | F24: TECHER | G24: Jean Fabrice | H24: 0693546553 | J24: 0693546553 | K24: GALAOR SQUATEUR | M24: locataire | N24: oui | S24: A activer | U24: 1023 | V24: non | W24: 0 | X24: non | AC24: https://t.me/motk_notification_bot?start=LTS-001-023 | AD24: 🏛️ Ville de Saint-Denis Service Habitat – Projet MOTK Bonjour Jean Fabrice TECHER Activez vos notifications logement : Lien : https://t.me/motk_notification_bot?start=LTS-001-023 Code secret : 1023 Étapes : 1) Cliquez sur le lien 2) Appuyez sur Start 3) Envoyez votre numéro de téléphone 4) Envoyez votre code secret.
A25: 1 | B25: Sainte Cloitlde | C25: LTS-001 | D25: LTS-001-024 | E25: ALAMANDAS | F25: TECHER | G25: Joseph Francis | H25: 0692487884 | J25: 0692487884 | M25: locataire | N25: oui | S25: A activer | U25: 1024 | V25: non | W25: 0 | X25: non | AC25: https://t.me/motk_notification_bot?start=LTS-001-024 | AD25: 🏛️ Ville de Saint-Denis Service Habitat – Projet MOTK Bonjour Joseph Francis TECHER Activez vos notifications logement : Lien : https://t.me/motk_notification_bot?start=LTS-001-024 Code secret : 1024 Étapes : 1) Cliquez sur le lien 2) Appuyez sur Start 3) Envoyez votre numéro de téléphone 4) Envoyez votre code secret.
A26: 1 | B26: Sainte Cloitlde | C26: LTS-001 | D26: LTS-001-025 | E26: ALAMANDAS | F26: VIRAPIN CAROUMBIN | G26: Marie-Josée | H26: 0692689202 | J26: 0692689202 | M26: locataire | N26: oui | S26: A activer | U26: 1025 | V26: non | W26: 0 | X26: non | AC26: https://t.me/motk_notification_bot?start=LTS-001-025 | AD26: 🏛️ Ville de Saint-Denis Service Habitat – Projet MOTK Bonjour Marie-Josée VIRAPIN CAROUMBIN Activez vos notifications logement : Lien : https://t.me/motk_notification_bot?start=LTS-001-025 Code secret : 1025 Étapes : 1) Cliquez sur le lien 2) Appuyez sur Start 3) Envoyez votre numéro de téléphone 4) Envoyez votre code secret.
A27: 1 | B27: Sainte Cloitlde | C27: LTS-001 | D27: LTS-001-026 | E27: ALAMANDAS | F27: CORRE | G27: Laurianne Emmanuelle | H27: 0692842718 | I27: 0692341364 | J27: 0692842718 | K27: PÈRE | MERE | M27: locataire | N27: oui | S27: A activer | U27: 1026 | V27: non | W27: 0 | X27: non | AC27: https://t.me/motk_notification_bot?start=LTS-001-026 | AD27: 🏛️ Ville de Saint-Denis Service Habitat – Projet MOTK Bonjour Laurianne Emmanuelle CORRE Activez vos notifications logement : Lien : https://t.me/motk_notification_bot?start=LTS-001-026 Code secret : 1026 Étapes : 1) Cliquez sur le lien 2) Appuyez sur Start 3) Envoyez votre numéro de téléphone 4) Envoyez votre code secret.
A28: 1 | B28: Sainte Cloitlde | C28: LTS-001 | D28: LTS-001-027 | E28: ALAMANDAS | F28: SEVERIN | G28: André Claude | H28: 0692922924 | I28: 0693283029 / 0692661125 | J28: 0692922924 | K28: sa fille | severin | M28: locataire | N28: oui | S28: A activer | U28: 1027 | V28: non | W28: 0 | X28: non | AC28: https://t.me/motk_notification_bot?start=LTS-001-027 | AD28: 🏛️ Ville de Saint-Denis Service Habitat – Projet MOTK Bonjour André Claude SEVERIN Activez vos notifications logement : Lien : https://t.me/motk_notification_bot?start=LTS-001-027 Code secret : 1027 Étapes : 1) Cliquez sur le lien 2) Appuyez sur Start 3) Envoyez votre numéro de téléphone 4) Envoyez votre code secret.
A29: 1 | B29: Sainte Cloitlde | C29: LTS-001 | D29: LTS-001-028 | E29: ALAMANDAS | F29: LAURENT | G29: Thomas | H29: 0692139045 | J29: 0692139045 | M29: locataire | N29: oui | S29: A activer | U29: 1028 | V29: non | W29: 0 | X29: non | AC29: https://t.me/motk_notification_bot?start=LTS-001-028 | AD29: 🏛️ Ville de Saint-Denis Service Habitat – Projet MOTK Bonjour Thomas LAURENT Activez vos notifications logement : Lien : https://t.me/motk_notification_bot?start=LTS-001-028 Code secret : 1028 Étapes : 1) Cliquez sur le lien 2) Appuyez sur Start 3) Envoyez votre numéro de téléphone 4) Envoyez votre code secret.
A30: 1 | B30: Sainte Cloitlde | C30: LTS-001 | D30: LTS-001-029 | E30: ALAMANDAS | F30: LAURENT | G30: Jean Alain | H30: 0692590826 | I30: 0692946258 / 0693823305 | J30: 0692590826 | M30: locataire | N30: oui | S30: A activer | U30: 1029 | V30: non | W30: 0 | X30: non | AC30: https://t.me/motk_notification_bot?start=LTS-001-029 | AD30: 🏛️ Ville de Saint-Denis Service Habitat – Projet MOTK Bonjour Jean Alain LAURENT Activez vos notifications logement : Lien : https://t.me/motk_notification_bot?start=LTS-001-029 Code secret : 1029 Étapes : 1) Cliquez sur le lien 2) Appuyez sur Start 3) Envoyez votre numéro de téléphone 4) Envoyez votre code secret.
A31: 1 | B31: Sainte Cloitlde | C31: LTS-001 | D31: LTS-001-030 | E31: ALAMANDAS | F31: FIBAC | G31: Marie Hélène | H31: 0692660767 | J31: 0692660767 | M31: locataire | N31: oui | S31: A activer | U31: 1030 | V31: non | W31: 0 | X31: non | AC31: https://t.me/motk_notification_bot?start=LTS-001-030 | AD31: 🏛️ Ville de Saint-Denis Service Habitat – Projet MOTK Bonjour Marie Hélène FIBAC Activez vos notifications logement : Lien : https://t.me/motk_notification_bot?start=LTS-001-030 Code secret : 1030 Étapes : 1) Cliquez sur le lien 2) Appuyez sur Start 3) Envoyez votre numéro de téléphone 4) Envoyez votre code secret.
A32: 1 | B32: Prima | C32: LTS-002 | D32: LTS-002-001 | E32: ATTES | F32: ANDRIANA | G32: Marie Françoise | H32: 0693525546 | I32: 0692547291 | J32: 0693525546 | K32: PIERRE ALFLECHE | M32: locataire | N32: oui | S32: A activer | U32: 1031 | V32: non | W32: 0 | X32: non | AC32: https://t.me/motk_notification_bot?start=LTS-002-001 | AD32: 🏛️ Ville de Saint-Denis Service Habitat – Projet MOTK Bonjour Marie Françoise ANDRIANA Activez vos notifications logement : Lien : https://t.me/motk_notification_bot?start=LTS-002-001 Code secret : 1031 Étapes : 1) Cliquez sur le lien 2) Appuyez sur Start 3) Envoyez votre numéro de téléphone 4) Envoyez votre code secret.
A33: 1 | B33: Prima | C33: LTS-002 | D33: LTS-002-002 | E33: ATTES | F33: HIVANHOE | G33: Jean Patrick | H33: 0262902947 | J33: 0262902947 | K33: UDAF | M33: locataire | N33: oui | S33: A activer | U33: 1032 | V33: non | W33: 0 | X33: non | AC33: https://t.me/motk_notification_bot?start=LTS-002-002 | AD33: 🏛️ Ville de Saint-Denis Service Habitat – Projet MOTK Bonjour Jean Patrick HIVANHOE Activez vos notifications logement : Lien : https://t.me/motk_notification_bot?start=LTS-002-002 Code secret : 1032 Étapes : 1) Cliquez sur le lien 2) Appuyez sur Start 3) Envoyez votre numéro de téléphone 4) Envoyez votre code secret.
A34: 1 | B34: Prima | C34: LTS-002 | D34: LTS-002-003 | E34: ATTES | F34: MASSEAUX | G34: Clarisse Alida | H34: 0692260455 | J34: 0692260455 | M34: locataire | N34: oui | S34: A activer | U34: 1033 | V34: non | W34: 0 | X34: non | AC34: https://t.me/motk_notification_bot?start=LTS-002-003 | AD34: 🏛️ Ville de Saint-Denis Service Habitat – Projet MOTK Bonjour Clarisse Alida MASSEAUX Activez vos notifications logement : Lien : https://t.me/motk_notification_bot?start=LTS-002-003 Code secret : 1033 Étapes : 1) Cliquez sur le lien 2) Appuyez sur Start 3) Envoyez votre numéro de téléphone 4) Envoyez votre code secret.
A35: 3 | B35: Le Brulé | C35: LTS-003 | D35: LTS-003-001 | E35: AZALEES | F35: IMAHO | G35: Emmanuelle Anne Gaëlle | H35: 0692631658 | I35: 0693111634 | J35: 0692631658 | K35: NUM W | M35: locataire | N35: oui | S35: A activer | U35: 1034 | V35: non | W35: 0 | X35: non | AC35: https://t.me/motk_notification_bot?start=LTS-003-001 | AD35: 🏛️ Ville de Saint-Denis Service Habitat – Projet MOTK Bonjour Emmanuelle Anne Gaëlle IMAHO Activez vos notifications logement : Lien : https://t.me/motk_notification_bot?start=LTS-003-001 Code secret : 1034 Étapes : 1) Cliquez sur le lien 2) Appuyez sur Start 3) Envoyez votre numéro de téléphone 4) Envoyez votre code secret.
A36: 3 | B36: Le Brulé | C36: LTS-003 | D36: LTS-003-002 | E36: AZALEES | F36: IFIANTEPIA | G36: occupé en attente decision | H36: 0692229197 | J36: 0692229197 | M36: locataire | N36: oui | S36: A activer | U36: 1035 | V36: non | W36: 0 | X36: non | AC36: https://t.me/motk_notification_bot?start=LTS-003-002 | AD36: 🏛️ Ville de Saint-Denis Service Habitat – Projet MOTK Bonjour occupé en attente decision IFIANTEPIA Activez vos notifications logement : Lien : https://t.me/motk_notification_bot?start=LTS-003-002 Code secret : 1035 Étapes : 1) Cliquez sur le lien 2) Appuyez sur Start 3) Envoyez votre numéro de téléphone 4) Envoyez votre code secret.
A37: 3 | B37: Le Brulé | C37: LTS-003 | D37: LTS-003-003 | E37: AZALEES | F37: THOMAS NÉE TURPIN | G37: Marie Micheline | H37: 0692587339 | J37: 0692587339 | M37: locataire | N37: oui | S37: A activer | U37: 1036 | V37: non | W37: 0 | X37: non | AC37: https://t.me/motk_notification_bot?start=LTS-003-003 | AD37: 🏛️ Ville de Saint-Denis Service Habitat – Projet MOTK Bonjour Marie Micheline THOMAS NÉE TURPIN Activez vos notifications logement : Lien : https://t.me/motk_notification_bot?start=LTS-003-003 Code secret : 1036 Étapes : 1) Cliquez sur le lien 2) Appuyez sur Start 3) Envoyez votre numéro de téléphone 4) Envoyez votre code secret.
A38: 3 | B38: Le Brulé | C38: LTS-003 | D38: LTS-003-004 | E38: AZALEES | F38: POLEYA | G38: Joachim | H38: 0692743656 | J38: 0692743656 | M38: locataire | N38: oui | S38: A activer | U38: 1037 | V38: non | W38: 0 | X38: non | AC38: https://t.me/motk_notification_bot?start=LTS-003-004 | AD38: 🏛️ Ville de Saint-Denis Service Habitat – Projet MOTK Bonjour Joachim POLEYA Activez vos notifications logement : Lien : https://t.me/motk_notification_bot?start=LTS-003-004 Code secret : 1037 Étapes : 1) Cliquez sur le lien 2) Appuyez sur Start 3) Envoyez votre numéro de téléphone 4) Envoyez votre code secret.
A39: 2 | B39: Marcadet | C39: LTS-004 | D39: LTS-004-001 | E39: BARBADINES | F39: ABDALAH BEDANI | G39: Marie Thérèse | H39: 0692128814 | J39: 0692128814 | M39: locataire | N39: oui | S39: A activer | U39: 1038 | V39: non | W39: 0 | X39: non | AC39: https://t.me/motk_notification_bot?start=LTS-004-001 | AD39: 🏛️ Ville de Saint-Denis Service Habitat – Projet MOTK Bonjour Marie Thérèse ABDALAH BEDANI Activez vos notifications logement : Lien : https://t.me/motk_notification_bot?start=LTS-004-001 Code secret : 1038 Étapes : 1) Cliquez sur le lien 2) Appuyez sur Start 3) Envoyez votre numéro de téléphone 4) Envoyez votre code secret.
A40: 2 | B40: Marcadet | C40: LTS-004 | D40: LTS-004-002 | E40: BARBADINES | F40: MAILLOT | H40: 0692209721 | J40: 0692209721 | M40: locataire | N40: oui | S40: A activer | U40: 1039 | V40: non | W40: 0 | X40: non | AC40: https://t.me/motk_notification_bot?start=LTS-004-002 | AD40: 🏛️ Ville de Saint-Denis Service Habitat – Projet MOTK Bonjour MAILLOT Activez vos notifications logement : Lien : https://t.me/motk_notification_bot?start=LTS-004-002 Code secret : 1039 Étapes : 1) Cliquez sur le lien 2) Appuyez sur Start 3) Envoyez votre numéro de téléphone 4) Envoyez votre code secret.
...

Sheet Referentiels
A1: Référentiels et listes déroulantes
A2: Ne pas saisir librement les statuts : utilisez ces listes pour éviter les erreurs
A3: OUI_NON | C3: STATUT_ACTIVATION | E3: CONTACT_ACTIF | G3: TYPE_CONTACT | I3: ORIGINE_DEMANDE | K3: STATUT_DEMANDE | M3: STATUT_DETAIL | O3: TYPE_TRAVAUX | Q3: URGENCE | S3: MODE_ATTRIBUTION | U3: NOTIFICATION | W3: STATUT_VENTE | Y3: STATUT_DIAG | AA3: STATUT_CHEQUE | AC3: STATUT_PAIEMENT | AE3: STATUT_DOSSIER | AG3: STATUT_MARCHE | AI3: MODE_PRESTATION | AK3: CANAL | AM3: VENTE_AUTORISEE
A4: oui | C4: A activer | E4: oui | G4: locataire | I4: locataire | K4: nouvelle | M4: en_attente | O4: plomberie | Q4: faible | S4: marche | U4: a_notifier | W4: demande_recue | Y4: a_faire | AA4: a_instruire | AC4: en_attente | AE4: ok | AG4: actif | AI4: titulaire_marche | AK4: Telegram | AM4: oui
A5: non | C5: oui | E5: non | G5: cooccupant | I5: agent | K5: analyse | M5: en_cours | O5: electricite | Q5: moyenne | S5: hors_marche | U5: envoyee | W5: en_instruction | Y5: fait | AA5: valide | AC5: depot_recu | AE5: a_regulariser | AG5: termine | AI5: hors_marche | AK5: SMS | AM5: non
C6: non | G6: référent | I6: entreprise | K6: validee | M6: termine | O6: toiture | Q6: urgente | S6: urgence | U6: non_concerne | W6: pret_signature | Y6: non_concerne | AA6: refuse | AC6: virement_effectue | AE6: incomplet | AG6: suspendu | AI6: urgence | AK6: Mail
C7: bloquee | G7: gestionnaire | I7: direction | K7: refusee | M7: bloque | O7: serrurerie | S7: consultation | W7: signature | AA7: non_concerne | AC7: non_concerne | AG7: a_lancer | AI7: consultation | AK7: Manuel
O8: assainissement | W8: realisee
O9: peinture | W9: refusee
O10: menuiserie
O11: vrd
O12: autre

Sheet LTS_Parc
A1: secteur | B1: quartier | C1: code_lts | D1: code_acces | E1: nom_lts | F1: adresse | G1: nombre_logements | H1: x | I1: y | J1: nom | K1: prenom | L1: telephone_principal | M1: telephone_secondaire | N1: remarques_contact | O1: a_vendre | P1: location_pure | Q1: a_vendre | R1: vente_statut | S1: x | T1: y | U1: contact_actif | V1: statut_global | W1: priorite | X1: niveau_sante
A2: 1 | B2: Sainte Cloitlde | C2: LTS-001 | D2: LTS-001-001 | E2: ALAMANDAS | F2: 15 Bloc 20 Rue des Alamandas | G2: 30 | H2: 68 | I2: 24 | J2: RIVIERE | K2: Fabienne | L2: 0692670367 | O2: non | P2: Résidence exclue du dispositif de vente | Q2: non | U2: =IF(COUNTIFS(Contacts_Activation!D:D,D2,Contacts_Activation!N:N,"oui")>0,"oui","non") -> oui | V2: =IF(COUNTIFS(Travaux!C:C,D2,Travaux!X:X,"en_cours")>0,"travaux_en_cours",IF(COUNTIFS(Ventes!C:C,D2,Ventes!L:L,"signature")>0,"vente_signature",IF(COUNTIFS(Ventes!C:C,D2,Ventes!AD:AD,"oui")>0,"vente_bloquee",IF(COUNTIFS(Gestion_Locative!C:C,D2,Gestion_Locative!O:O,"incomplet")>0,"gestion_fragile","stable")))) -> vente_bloquee
A3: 1 | B3: Sainte Cloitlde | C3: LTS-001 | D3: LTS-001-002 | E3: ALAMANDAS | F3: 26 Bloc 24 Rue des Alamandas | G3: 30 | H3: 68 | I3: 24 | J3: ARAYE | K3: Evelyne | L3: 0262294396 | M3: 0692085376 | O3: non | P3: Résidence exclue du dispositif de vente | Q3: non | U3: =IF(COUNTIFS(Contacts_Activation!D:D,D3,Contacts_Activation!N:N,"oui")>0,"oui","non") -> oui | V3: =IF(COUNTIFS(Travaux!C:C,D3,Travaux!X:X,"en_cours")>0,"travaux_en_cours",IF(COUNTIFS(Ventes!C:C,D3,Ventes!L:L,"signature")>0,"vente_signature",IF(COUNTIFS(Ventes!C:C,D3,Ventes!AD:AD,"oui")>0,"vente_bloquee",IF(COUNTIFS(Gestion_Locative!C:C,D3,Gestion_Locative!O:O,"incomplet")>0,"gestion_fragile","stable")))) -> vente_bloquee
A4: 1 | B4: Sainte Cloitlde | C4: LTS-001 | D4: LTS-001-003 | E4: ALAMANDAS | F4: 19 Bloc 22 Rue des Alamandas | G4: 30 | H4: 68 | I4: 24 | J4: ARLANDON | K4: Jean Luc | L4: 0692253329 | M4: 0692373955 | N4: FREDERICK ARLANDON | O4: non | P4: Résidence exclue du dispositif de vente | Q4: non | U4: =IF(COUNTIFS(Contacts_Activation!D:D,D4,Contacts_Activation!N:N,"oui")>0,"oui","non") -> oui | V4: =IF(COUNTIFS(Travaux!C:C,D4,Travaux!X:X,"en_cours")>0,"travaux_en_cours",IF(COUNTIFS(Ventes!C:C,D4,Ventes!L:L,"signature")>0,"vente_signature",IF(COUNTIFS(Ventes!C:C,D4,Ventes!AD:AD,"oui")>0,"vente_bloquee",IF(COUNTIFS(Gestion_Locative!C:C,D4,Gestion_Locative!O:O,"incomplet")>0,"gestion_fragile","stable")))) -> vente_bloquee
A5: 1 | B5: Sainte Cloitlde | C5: LTS-001 | D5: LTS-001-004 | E5: ALAMANDAS | F5: 27 Bloc 24 Rue des Alamandas | G5: 30 | H5: 68 | I5: 24 | J5: CAZAMBO | K5: Jean François | L5: 0693137209 | O5: non | P5: Résidence exclue du dispositif de vente | Q5: non | U5: =IF(COUNTIFS(Contacts_Activation!D:D,D5,Contacts_Activation!N:N,"oui")>0,"oui","non") -> oui | V5: =IF(COUNTIFS(Travaux!C:C,D5,Travaux!X:X,"en_cours")>0,"travaux_en_cours",IF(COUNTIFS(Ventes!C:C,D5,Ventes!L:L,"signature")>0,"vente_signature",IF(COUNTIFS(Ventes!C:C,D5,Ventes!AD:AD,"oui")>0,"vente_bloquee",IF(COUNTIFS(Gestion_Locative!C:C,D5,Gestion_Locative!O:O,"incomplet")>0,"gestion_fragile","stable")))) -> vente_bloquee
A6: 1 | B6: Sainte Cloitlde | C6: LTS-001 | D6: LTS-001-005 | E6: ALAMANDAS | F6: 11 Bloc 18 Rue des Alamandas | G6: 30 | H6: 68 | I6: 24 | J6: CHANE LAW | K6: Jimmy | L6: 0692957824 | O6: non | P6: Résidence exclue du dispositif de vente | Q6: non | U6: =IF(COUNTIFS(Contacts_Activation!D:D,D6,Contacts_Activation!N:N,"oui")>0,"oui","non") -> oui | V6: =IF(COUNTIFS(Travaux!C:C,D6,Travaux!X:X,"en_cours")>0,"travaux_en_cours",IF(COUNTIFS(Ventes!C:C,D6,Ventes!L:L,"signature")>0,"vente_signature",IF(COUNTIFS(Ventes!C:C,D6,Ventes!AD:AD,"oui")>0,"vente_bloquee",IF(COUNTIFS(Gestion_Locative!C:C,D6,Gestion_Locative!O:O,"incomplet")>0,"gestion_fragile","stable")))) -> vente_bloquee
A7: 1 | B7: Sainte Cloitlde | C7: LTS-001 | D7: LTS-001-006 | E7: ALAMANDAS | F7: 24 Bloc 22 Rue des Alamandas | G7: 30 | H7: 68 | I7: 24 | J7: METELLUS | K7: Stéphane | L7: 0693044649 | O7: non | P7: Résidence exclue du dispositif de vente | Q7: non | U7: =IF(COUNTIFS(Contacts_Activation!D:D,D7,Contacts_Activation!N:N,"oui")>0,"oui","non") -> oui | V7: =IF(COUNTIFS(Travaux!C:C,D7,Travaux!X:X,"en_cours")>0,"travaux_en_cours",IF(COUNTIFS(Ventes!C:C,D7,Ventes!L:L,"signature")>0,"vente_signature",IF(COUNTIFS(Ventes!C:C,D7,Ventes!AD:AD,"oui")>0,"vente_bloquee",IF(COUNTIFS(Gestion_Locative!C:C,D7,Gestion_Locative!O:O,"incomplet")>0,"gestion_fragile","stable")))) -> vente_bloquee
A8: 1 | B8: Sainte Cloitlde | C8: LTS-001 | D8: LTS-001-007 | E8: ALAMANDAS | F8: 12 Bloc 18 Rue des Alamandas | G8: 30 | H8: 68 | I8: 24 | J8: FICHORA | K8: Armand | L8: 0262284589 | O8: non | P8: Résidence exclue du dispositif de vente | Q8: non | U8: =IF(COUNTIFS(Contacts_Activation!D:D,D8,Contacts_Activation!N:N,"oui")>0,"oui","non") -> oui | V8: =IF(COUNTIFS(Travaux!C:C,D8,Travaux!X:X,"en_cours")>0,"travaux_en_cours",IF(COUNTIFS(Ventes!C:C,D8,Ventes!L:L,"signature")>0,"vente_signature",IF(COUNTIFS(Ventes!C:C,D8,Ventes!AD:AD,"oui")>0,"vente_bloquee",IF(COUNTIFS(Gestion_Locative!C:C,D8,Gestion_Locative!O:O,"incomplet")>0,"gestion_fragile","stable")))) -> vente_bloquee
A9: 1 | B9: Sainte Cloitlde | C9: LTS-001 | D9: LTS-001-008 | E9: ALAMANDAS | F9: 29 Bloc 24 Rue des Alamandas | G9: 30 | H9: 68 | I9: 24 | J9: LOUISE | K9: Marie | L9: 0693051870 | N9: emmanuelle Boyer | O9: non | P9: Résidence exclue du dispositif de vente | Q9: non | U9: =IF(COUNTIFS(Contacts_Activation!D:D,D9,Contacts_Activation!N:N,"oui")>0,"oui","non") -> oui | V9: =IF(COUNTIFS(Travaux!C:C,D9,Travaux!X:X,"en_cours")>0,"travaux_en_cours",IF(COUNTIFS(Ventes!C:C,D9,Ventes!L:L,"signature")>0,"vente_signature",IF(COUNTIFS(Ventes!C:C,D9,Ventes!AD:AD,"oui")>0,"vente_bloquee",IF(COUNTIFS(Gestion_Locative!C:C,D9,Gestion_Locative!O:O,"incomplet")>0,"gestion_fragile","stable")))) -> vente_bloquee
A10: 1 | B10: Sainte Cloitlde | C10: LTS-001 | D10: LTS-001-009 | E10: ALAMANDAS | F10: 13 Bloc 20 Rue des Alamandas | G10: 30 | H10: 68 | I10: 24 | J10: GALTIER | K10: Rita Marie | L10: 0262293081 | M10: 0692898654 | N10: fils | O10: non | P10: Résidence exclue du dispositif de vente | Q10: non | U10: =IF(COUNTIFS(Contacts_Activation!D:D,D10,Contacts_Activation!N:N,"oui")>0,"oui","non") -> oui | V10: =IF(COUNTIFS(Travaux!C:C,D10,Travaux!X:X,"en_cours")>0,"travaux_en_cours",IF(COUNTIFS(Ventes!C:C,D10,Ventes!L:L,"signature")>0,"vente_signature",IF(COUNTIFS(Ventes!C:C,D10,Ventes!AD:AD,"oui")>0,"vente_bloquee",IF(COUNTIFS(Gestion_Locative!C:C,D10,Gestion_Locative!O:O,"incomplet")>0,"gestion_fragile","stable")))) -> vente_bloquee
A11: 1 | B11: Sainte Cloitlde | C11: LTS-001 | D11: LTS-001-010 | E11: ALAMANDAS | F11: 25 Bloc 24 Rue des Alamandas | G11: 30 | H11: 68 | I11: 24 | J11: GERVILLE | K11: Rose May | L11: 0692464983 | O11: non | P11: Résidence exclue du dispositif de vente | Q11: non | U11: =IF(COUNTIFS(Contacts_Activation!D:D,D11,Contacts_Activation!N:N,"oui")>0,"oui","non") -> oui | V11: =IF(COUNTIFS(Travaux!C:C,D11,Travaux!X:X,"en_cours")>0,"travaux_en_cours",IF(COUNTIFS(Ventes!C:C,D11,Ventes!L:L,"signature")>0,"vente_signature",IF(COUNTIFS(Ventes!C:C,D11,Ventes!AD:AD,"oui")>0,"vente_bloquee",IF(COUNTIFS(Gestion_Locative!C:C,D11,Gestion_Locative!O:O,"incomplet")>0,"gestion_fragile","stable")))) -> vente_bloquee
A12: 1 | B12: Sainte Cloitlde | C12: LTS-001 | D12: LTS-001-011 | E12: ALAMANDAS | F12: 2 Bloc 16 Rue des Alamandas | G12: 30 | H12: 68 | I12: 24 | J12: GRENIER | K12: Ruffine Marie | L12: 0262503633 | M12: 0692190983 | N12: OU | O12: non | P12: Résidence exclue du dispositif de vente | Q12: non | U12: =IF(COUNTIFS(Contacts_Activation!D:D,D12,Contacts_Activation!N:N,"oui")>0,"oui","non") -> oui | V12: =IF(COUNTIFS(Travaux!C:C,D12,Travaux!X:X,"en_cours")>0,"travaux_en_cours",IF(COUNTIFS(Ventes!C:C,D12,Ventes!L:L,"signature")>0,"vente_signature",IF(COUNTIFS(Ventes!C:C,D12,Ventes!AD:AD,"oui")>0,"vente_bloquee",IF(COUNTIFS(Gestion_Locative!C:C,D12,Gestion_Locative!O:O,"incomplet")>0,"gestion_fragile","stable")))) -> vente_bloquee
A13: 1 | B13: Sainte Cloitlde | C13: LTS-001 | D13: LTS-001-012 | E13: ALAMANDAS | F13: 4 Bloc 16 Rue des Alamandas | G13: 30 | H13: 68 | I13: 24 | J13: SAUTRON | K13: Willy David | L13: 0693634302 | M13: 0692084218 / 0692494271 | N13: Mme SAUTRON | O13: non | P13: Résidence exclue du dispositif de vente | Q13: non | U13: =IF(COUNTIFS(Contacts_Activation!D:D,D13,Contacts_Activation!N:N,"oui")>0,"oui","non") -> oui | V13: =IF(COUNTIFS(Travaux!C:C,D13,Travaux!X:X,"en_cours")>0,"travaux_en_cours",IF(COUNTIFS(Ventes!C:C,D13,Ventes!L:L,"signature")>0,"vente_signature",IF(COUNTIFS(Ventes!C:C,D13,Ventes!AD:AD,"oui")>0,"vente_bloquee",IF(COUNTIFS(Gestion_Locative!C:C,D13,Gestion_Locative!O:O,"incomplet")>0,"gestion_fragile","stable")))) -> vente_bloquee
A14: 1 | B14: Sainte Cloitlde | C14: LTS-001 | D14: LTS-001-013 | E14: ALAMANDAS | F14: 9 Bloc 18 Rue des Alamandas | G14: 30 | H14: 68 | I14: 24 | J14: LAFABLE | K14: Philippe | L14: 0692467006 | O14: non | P14: Résidence exclue du dispositif de vente | Q14: non | U14: =IF(COUNTIFS(Contacts_Activation!D:D,D14,Contacts_Activation!N:N,"oui")>0,"oui","non") -> oui | V14: =IF(COUNTIFS(Travaux!C:C,D14,Travaux!X:X,"en_cours")>0,"travaux_en_cours",IF(COUNTIFS(Ventes!C:C,D14,Ventes!L:L,"signature")>0,"vente_signature",IF(COUNTIFS(Ventes!C:C,D14,Ventes!AD:AD,"oui")>0,"vente_bloquee",IF(COUNTIFS(Gestion_Locative!C:C,D14,Gestion_Locative!O:O,"incomplet")>0,"gestion_fragile","stable")))) -> vente_bloquee
A15: 1 | B15: Sainte Cloitlde | C15: LTS-001 | D15: LTS-001-014 | E15: ALAMANDAS | F15: 14 Bloc 20 Rue des Alamandas | G15: 30 | H15: 68 | I15: 24 | J15: LAURENT | K15: Jean René | L15: 0262289120 | O15: non | P15: Résidence exclue du dispositif de vente | Q15: non | U15: =IF(COUNTIFS(Contacts_Activation!D:D,D15,Contacts_Activation!N:N,"oui")>0,"oui","non") -> oui | V15: =IF(COUNTIFS(Travaux!C:C,D15,Travaux!X:X,"en_cours")>0,"travaux_en_cours",IF(COUNTIFS(Ventes!C:C,D15,Ventes!L:L,"signature")>0,"vente_signature",IF(COUNTIFS(Ventes!C:C,D15,Ventes!AD:AD,"oui")>0,"vente_bloquee",IF(COUNTIFS(Gestion_Locative!C:C,D15,Gestion_Locative!O:O,"incomplet")>0,"gestion_fragile","stable")))) -> vente_bloquee
A16: 1 | B16: Sainte Cloitlde | C16: LTS-001 | D16: LTS-001-015 | E16: ALAMANDAS | F16: 16 Bloc 20 Rue des Alamandas | G16: 30 | H16: 68 | I16: 24 | J16: LAURENT | K16: Jean Bernard | L16: 0692916258 | O16: non | P16: Résidence exclue du dispositif de vente | Q16: non | U16: =IF(COUNTIFS(Contacts_Activation!D:D,D16,Contacts_Activation!N:N,"oui")>0,"oui","non") -> oui | V16: =IF(COUNTIFS(Travaux!C:C,D16,Travaux!X:X,"en_cours")>0,"travaux_en_cours",IF(COUNTIFS(Ventes!C:C,D16,Ventes!L:L,"signature")>0,"vente_signature",IF(COUNTIFS(Ventes!C:C,D16,Ventes!AD:AD,"oui")>0,"vente_bloquee",IF(COUNTIFS(Gestion_Locative!C:C,D16,Gestion_Locative!O:O,"incomplet")>0,"gestion_fragile","stable")))) -> vente_bloquee
A17: 1 | B17: Sainte Cloitlde | C17: LTS-001 | D17: LTS-001-016 | E17: ALAMANDAS | F17: 3 Bloc 16 Rue des Alamandas | G17: 30 | H17: 68 | I17: 24 | J17: MARKA | K17: Claude | L17: 0692906779 | O17: non | P17: Résidence exclue du dispositif de vente | Q17: non | U17: =IF(COUNTIFS(Contacts_Activation!D:D,D17,Contacts_Activation!N:N,"oui")>0,"oui","non") -> oui | V17: =IF(COUNTIFS(Travaux!C:C,D17,Travaux!X:X,"en_cours")>0,"travaux_en_cours",IF(COUNTIFS(Ventes!C:C,D17,Ventes!L:L,"signature")>0,"vente_signature",IF(COUNTIFS(Ventes!C:C,D17,Ventes!AD:AD,"oui")>0,"vente_bloquee",IF(COUNTIFS(Gestion_Locative!C:C,D17,Gestion_Locative!O:O,"incomplet")>0,"gestion_fragile","stable")))) -> vente_bloquee
A18: 1 | B18: Sainte Cloitlde | C18: LTS-001 | D18: LTS-001-017 | E18: ALAMANDAS | F18: 30 Bloc 24 Rue des Alamandas | G18: 30 | H18: 68 | I18: 24 | J18: MOUTOUSSAMY | K18: Jacques Antoine | L18: 0692807626 | M18: 0262190122 | O18: non | P18: Résidence exclue du dispositif de vente | Q18: non | U18: =IF(COUNTIFS(Contacts_Activation!D:D,D18,Contacts_Activation!N:N,"oui")>0,"oui","non") -> oui | V18: =IF(COUNTIFS(Travaux!C:C,D18,Travaux!X:X,"en_cours")>0,"travaux_en_cours",IF(COUNTIFS(Ventes!C:C,D18,Ventes!L:L,"signature")>0,"vente_signature",IF(COUNTIFS(Ventes!C:C,D18,Ventes!AD:AD,"oui")>0,"vente_bloquee",IF(COUNTIFS(Gestion_Locative!C:C,D18,Gestion_Locative!O:O,"incomplet")>0,"gestion_fragile","stable")))) -> vente_bloquee
A19: 1 | B19: Sainte Cloitlde | C19: LTS-001 | D19: LTS-001-018 | E19: ALAMANDAS | F19: 20 Bloc 22 Rue des Alamandas | G19: 30 | H19: 68 | I19: 24 | J19: PAYET | K19: Josiane Aline | L19: 0262504956 | M19: 0692677087 | O19: non | P19: Résidence exclue du dispositif de vente | Q19: non | U19: =IF(COUNTIFS(Contacts_Activation!D:D,D19,Contacts_Activation!N:N,"oui")>0,"oui","non") -> oui | V19: =IF(COUNTIFS(Travaux!C:C,D19,Travaux!X:X,"en_cours")>0,"travaux_en_cours",IF(COUNTIFS(Ventes!C:C,D19,Ventes!L:L,"signature")>0,"vente_signature",IF(COUNTIFS(Ventes!C:C,D19,Ventes!AD:AD,"oui")>0,"vente_bloquee",IF(COUNTIFS(Gestion_Locative!C:C,D19,Gestion_Locative!O:O,"incomplet")>0,"gestion_fragile","stable")))) -> vente_bloquee
A20: 1 | B20: Sainte Cloitlde | C20: LTS-001 | D20: LTS-001-019 | E20: ALAMANDAS | F20: 8 Bloc 18 Rue des Alamandas | G20: 30 | H20: 68 | I20: 24 | J20: ROBERT | K20: Jean Patrick | L20: 0692668371 | M20: 0692916112 | O20: non | P20: Résidence exclue du dispositif de vente | Q20: non | U20: =IF(COUNTIFS(Contacts_Activation!D:D,D20,Contacts_Activation!N:N,"oui")>0,"oui","non") -> oui | V20: =IF(COUNTIFS(Travaux!C:C,D20,Travaux!X:X,"en_cours")>0,"travaux_en_cours",IF(COUNTIFS(Ventes!C:C,D20,Ventes!L:L,"signature")>0,"vente_signature",IF(COUNTIFS(Ventes!C:C,D20,Ventes!AD:AD,"oui")>0,"vente_bloquee",IF(COUNTIFS(Gestion_Locative!C:C,D20,Gestion_Locative!O:O,"incomplet")>0,"gestion_fragile","stable")))) -> vente_bloquee
A21: 1 | B21: Sainte Cloitlde | C21: LTS-001 | D21: LTS-001-020 | E21: ALAMANDAS | F21: 5 Bloc 16 Rue des Alamandas | G21: 30 | H21: 68 | I21: 24 | J21: REFANE | K21: Marie Virginie | L21: 0692860902 | O21: non | P21: Résidence exclue du dispositif de vente | Q21: non | U21: =IF(COUNTIFS(Contacts_Activation!D:D,D21,Contacts_Activation!N:N,"oui")>0,"oui","non") -> oui | V21: =IF(COUNTIFS(Travaux!C:C,D21,Travaux!X:X,"en_cours")>0,"travaux_en_cours",IF(COUNTIFS(Ventes!C:C,D21,Ventes!L:L,"signature")>0,"vente_signature",IF(COUNTIFS(Ventes!C:C,D21,Ventes!AD:AD,"oui")>0,"vente_bloquee",IF(COUNTIFS(Gestion_Locative!C:C,D21,Gestion_Locative!O:O,"incomplet")>0,"gestion_fragile","stable")))) -> vente_bloquee
A22: 1 | B22: Sainte Cloitlde | C22: LTS-001 | D22: LTS-001-021 | E22: ALAMANDAS | F22: 6 Bloc 16 Rue des Alamandas | G22: 30 | H22: 68 | I22: 24 | J22: SINAPAYEN SINAMALE | K22: Henriette | L22: 0693860123 | M22: 0692143045 | N22: petit fils | O22: non | P22: Résidence exclue du dispositif de vente | Q22: non | U22: =IF(COUNTIFS(Contacts_Activation!D:D,D22,Contacts_Activation!N:N,"oui")>0,"oui","non") -> oui | V22: =IF(COUNTIFS(Travaux!C:C,D22,Travaux!X:X,"en_cours")>0,"travaux_en_cours",IF(COUNTIFS(Ventes!C:C,D22,Ventes!L:L,"signature")>0,"vente_signature",IF(COUNTIFS(Ventes!C:C,D22,Ventes!AD:AD,"oui")>0,"vente_bloquee",IF(COUNTIFS(Gestion_Locative!C:C,D22,Gestion_Locative!O:O,"incomplet")>0,"gestion_fragile","stable")))) -> vente_bloquee
A23: 1 | B23: Sainte Cloitlde | C23: LTS-001 | D23: LTS-001-022 | E23: ALAMANDAS | F23: 7 Bloc 18 Rue des Alamandas | G23: 30 | H23: 68 | I23: 24 | J23: MARKA | K23: GREGORY | L23: 0692843883 | O23: non | P23: Résidence exclue du dispositif de vente | Q23: non | U23: =IF(COUNTIFS(Contacts_Activation!D:D,D23,Contacts_Activation!N:N,"oui")>0,"oui","non") -> oui | V23: =IF(COUNTIFS(Travaux!C:C,D23,Travaux!X:X,"en_cours")>0,"travaux_en_cours",IF(COUNTIFS(Ventes!C:C,D23,Ventes!L:L,"signature")>0,"vente_signature",IF(COUNTIFS(Ventes!C:C,D23,Ventes!AD:AD,"oui")>0,"vente_bloquee",IF(COUNTIFS(Gestion_Locative!C:C,D23,Gestion_Locative!O:O,"incomplet")>0,"gestion_fragile","stable")))) -> vente_bloquee
A24: 1 | B24: Sainte Cloitlde | C24: LTS-001 | D24: LTS-001-023 | E24: ALAMANDAS | F24: 10 Bloc 18 Rue des Alamandas | G24: 30 | H24: 68 | I24: 24 | J24: TECHER | K24: Jean Fabrice | L24: 0693546553 | N24: GALAOR SQUATEUR | O24: non | P24: Résidence exclue du dispositif de vente | Q24: non | U24: =IF(COUNTIFS(Contacts_Activation!D:D,D24,Contacts_Activation!N:N,"oui")>0,"oui","non") -> oui | V24: =IF(COUNTIFS(Travaux!C:C,D24,Travaux!X:X,"en_cours")>0,"travaux_en_cours",IF(COUNTIFS(Ventes!C:C,D24,Ventes!L:L,"signature")>0,"vente_signature",IF(COUNTIFS(Ventes!C:C,D24,Ventes!AD:AD,"oui")>0,"vente_bloquee",IF(COUNTIFS(Gestion_Locative!C:C,D24,Gestion_Locative!O:O,"incomplet")>0,"gestion_fragile","stable")))) -> vente_bloquee
A25: 1 | B25: Sainte Cloitlde | C25: LTS-001 | D25: LTS-001-024 | E25: ALAMANDAS | F25: 1 Bloc 16 Rue des Alamandas | G25: 30 | H25: 68 | I25: 24 | J25: TECHER | K25: Joseph Francis | L25: 0692487884 | O25: non | P25: Résidence exclue du dispositif de vente | Q25: non | U25: =IF(COUNTIFS(Contacts_Activation!D:D,D25,Contacts_Activation!N:N,"oui")>0,"oui","non") -> oui | V25: =IF(COUNTIFS(Travaux!C:C,D25,Travaux!X:X,"en_cours")>0,"travaux_en_cours",IF(COUNTIFS(Ventes!C:C,D25,Ventes!L:L,"signature")>0,"vente_signature",IF(COUNTIFS(Ventes!C:C,D25,Ventes!AD:AD,"oui")>0,"vente_bloquee",IF(COUNTIFS(Gestion_Locative!C:C,D25,Gestion_Locative!O:O,"incomplet")>0,"gestion_fragile","stable")))) -> vente_bloquee
A26: 1 | B26: Sainte Cloitlde | C26: LTS-001 | D26: LTS-001-025 | E26: ALAMANDAS | F26: 23 Bloc 22 Rue des Alamandas | G26: 30 | H26: 68 | I26: 24 | J26: VIRAPIN CAROUMBIN | K26: Marie-Josée | L26: 0692689202 | O26: non | P26: Résidence exclue du dispositif de vente | Q26: non | U26: =IF(COUNTIFS(Contacts_Activation!D:D,D26,Contacts_Activation!N:N,"oui")>0,"oui","non") -> oui | V26: =IF(COUNTIFS(Travaux!C:C,D26,Travaux!X:X,"en_cours")>0,"travaux_en_cours",IF(COUNTIFS(Ventes!C:C,D26,Ventes!L:L,"signature")>0,"vente_signature",IF(COUNTIFS(Ventes!C:C,D26,Ventes!AD:AD,"oui")>0,"vente_bloquee",IF(COUNTIFS(Gestion_Locative!C:C,D26,Gestion_Locative!O:O,"incomplet")>0,"gestion_fragile","stable")))) -> vente_bloquee
A27: 1 | B27: Sainte Cloitlde | C27: LTS-001 | D27: LTS-001-026 | E27: ALAMANDAS | F27: 17 Bloc 20 Rue des Alamandas | G27: 30 | H27: 68 | I27: 24 | J27: CORRE | K27: Laurianne Emmanuelle | L27: 0692842718 | M27: 0692341364 | N27: PÈRE | MERE | O27: non | P27: Résidence exclue du dispositif de vente | Q27: non | U27: =IF(COUNTIFS(Contacts_Activation!D:D,D27,Contacts_Activation!N:N,"oui")>0,"oui","non") -> oui | V27: =IF(COUNTIFS(Travaux!C:C,D27,Travaux!X:X,"en_cours")>0,"travaux_en_cours",IF(COUNTIFS(Ventes!C:C,D27,Ventes!L:L,"signature")>0,"vente_signature",IF(COUNTIFS(Ventes!C:C,D27,Ventes!AD:AD,"oui")>0,"vente_bloquee",IF(COUNTIFS(Gestion_Locative!C:C,D27,Gestion_Locative!O:O,"incomplet")>0,"gestion_fragile","stable")))) -> vente_bloquee
A28: 1 | B28: Sainte Cloitlde | C28: LTS-001 | D28: LTS-001-027 | E28: ALAMANDAS | F28: 21 Bloc 22 Rue des Alamandas | G28: 30 | H28: 68 | I28: 24 | J28: SEVERIN | K28: André Claude | L28: 0692922924 | M28: 0693283029 / 0692661125 | N28: sa fille | severin | O28: non | P28: Résidence exclue du dispositif de vente | Q28: non | U28: =IF(COUNTIFS(Contacts_Activation!D:D,D28,Contacts_Activation!N:N,"oui")>0,"oui","non") -> oui | V28: =IF(COUNTIFS(Travaux!C:C,D28,Travaux!X:X,"en_cours")>0,"travaux_en_cours",IF(COUNTIFS(Ventes!C:C,D28,Ventes!L:L,"signature")>0,"vente_signature",IF(COUNTIFS(Ventes!C:C,D28,Ventes!AD:AD,"oui")>0,"vente_bloquee",IF(COUNTIFS(Gestion_Locative!C:C,D28,Gestion_Locative!O:O,"incomplet")>0,"gestion_fragile","stable")))) -> vente_bloquee
A29: 1 | B29: Sainte Cloitlde | C29: LTS-001 | D29: LTS-001-028 | E29: ALAMANDAS | F29: 22 Bloc 22 Rue des Alamandas | G29: 30 | H29: 68 | I29: 24 | J29: LAURENT | K29: Thomas | L29: 0692139045 | O29: non | P29: Résidence exclue du dispositif de vente | Q29: non | U29: =IF(COUNTIFS(Contacts_Activation!D:D,D29,Contacts_Activation!N:N,"oui")>0,"oui","non") -> oui | V29: =IF(COUNTIFS(Travaux!C:C,D29,Travaux!X:X,"en_cours")>0,"travaux_en_cours",IF(COUNTIFS(Ventes!C:C,D29,Ventes!L:L,"signature")>0,"vente_signature",IF(COUNTIFS(Ventes!C:C,D29,Ventes!AD:AD,"oui")>0,"vente_bloquee",IF(COUNTIFS(Gestion_Locative!C:C,D29,Gestion_Locative!O:O,"incomplet")>0,"gestion_fragile","stable")))) -> vente_bloquee
A30: 1 | B30: Sainte Cloitlde | C30: LTS-001 | D30: LTS-001-029 | E30: ALAMANDAS | F30: 28 Bloc 24 Rue des Alamandas | G30: 30 | H30: 68 | I30: 24 | J30: LAURENT | K30: Jean Alain | L30: 0692590826 | M30: 0692946258 / 0693823305 | O30: non | P30: Résidence exclue du dispositif de vente | Q30: non | U30: =IF(COUNTIFS(Contacts_Activation!D:D,D30,Contacts_Activation!N:N,"oui")>0,"oui","non") -> oui | V30: =IF(COUNTIFS(Travaux!C:C,D30,Travaux!X:X,"en_cours")>0,"travaux_en_cours",IF(COUNTIFS(Ventes!C:C,D30,Ventes!L:L,"signature")>0,"vente_signature",IF(COUNTIFS(Ventes!C:C,D30,Ventes!AD:AD,"oui")>0,"vente_bloquee",IF(COUNTIFS(Gestion_Locative!C:C,D30,Gestion_Locative!O:O,"incomplet")>0,"gestion_fragile","stable")))) -> vente_bloquee
A31: 1 | B31: Sainte Cloitlde | C31: LTS-001 | D31: LTS-001-030 | E31: ALAMANDAS | F31: 18 Bloc 20 Rue des Alamandas | G31: 30 | H31: 68 | I31: 24 | J31: FIBAC | K31: Marie Hélène | L31: 0692660767 | O31: non | P31: Résidence exclue du dispositif de vente | Q31: non | U31: =IF(COUNTIFS(Contacts_Activation!D:D,D31,Contacts_Activation!N:N,"oui")>0,"oui","non") -> oui | V31: =IF(COUNTIFS(Travaux!C:C,D31,Travaux!X:X,"en_cours")>0,"travaux_en_cours",IF(COUNTIFS(Ventes!C:C,D31,Ventes!L:L,"signature")>0,"vente_signature",IF(COUNTIFS(Ventes!C:C,D31,Ventes!AD:AD,"oui")>0,"vente_bloquee",IF(COUNTIFS(Gestion_Locative!C:C,D31,Gestion_Locative!O:O,"incomplet")>0,"gestion_fragile","stable")))) -> vente_bloquee
A32: 1 | B32: Prima | C32: LTS-002 | D32: LTS-002-001 | E32: ATTES | F32: 37 Rue du Stade de L'Est | G32: 3 | H32: 75 | I32: 35 | J32: ANDRIANA | K32: Marie Françoise | L32: 0693525546 | M32: 0692547291 | N32: PIERRE ALFLECHE | O32: oui | Q32: non | U32: =IF(COUNTIFS(Contacts_Activation!D:D,D32,Contacts_Activation!N:N,"oui")>0,"oui","non") -> oui | V32: =IF(COUNTIFS(Travaux!C:C,D32,Travaux!X:X,"en_cours")>0,"travaux_en_cours",IF(COUNTIFS(Ventes!C:C,D32,Ventes!L:L,"signature")>0,"vente_signature",IF(COUNTIFS(Ventes!C:C,D32,Ventes!AD:AD,"oui")>0,"vente_bloquee",IF(COUNTIFS(Gestion_Locative!C:C,D32,Gestion_Locative!O:O,"incomplet")>0,"gestion_fragile","stable")))) -> vente_bloquee
A33: 1 | B33: Prima | C33: LTS-002 | D33: LTS-002-002 | E33: ATTES | F33: 23 Rue des Lavandières | G33: 3 | H33: 75 | I33: 35 | J33: HIVANHOE | K33: Jean Patrick | L33: 0262902947 | N33: UDAF | O33: oui | Q33: non | U33: =IF(COUNTIFS(Contacts_Activation!D:D,D33,Contacts_Activation!N:N,"oui")>0,"oui","non") -> oui | V33: =IF(COUNTIFS(Travaux!C:C,D33,Travaux!X:X,"en_cours")>0,"travaux_en_cours",IF(COUNTIFS(Ventes!C:C,D33,Ventes!L:L,"signature")>0,"vente_signature",IF(COUNTIFS(Ventes!C:C,D33,Ventes!AD:AD,"oui")>0,"vente_bloquee",IF(COUNTIFS(Gestion_Locative!C:C,D33,Gestion_Locative!O:O,"incomplet")>0,"gestion_fragile","stable")))) -> vente_bloquee
A34: 1 | B34: Prima | C34: LTS-002 | D34: LTS-002-003 | E34: ATTES | F34: 11 Rue des Lavandières | G34: 3 | H34: 75 | I34: 35 | J34: MASSEAUX | K34: Clarisse Alida | L34: 0692260455 | O34: oui | Q34: non | U34: =IF(COUNTIFS(Contacts_Activation!D:D,D34,Contacts_Activation!N:N,"oui")>0,"oui","non") -> oui | V34: =IF(COUNTIFS(Travaux!C:C,D34,Travaux!X:X,"en_cours")>0,"travaux_en_cours",IF(COUNTIFS(Ventes!C:C,D34,Ventes!L:L,"signature")>0,"vente_signature",IF(COUNTIFS(Ventes!C:C,D34,Ventes!AD:AD,"oui")>0,"vente_bloquee",IF(COUNTIFS(Gestion_Locative!C:C,D34,Gestion_Locative!O:O,"incomplet")>0,"gestion_fragile","stable")))) -> vente_bloquee
A35: 3 | B35: Le Brulé | C35: LTS-003 | D35: LTS-003-001 | E35: AZALEES | F35: 107 Route des Azalées | G35: 4 | H35: 48 | I35: 58 | J35: IMAHO | K35: Emmanuelle Anne Gaëlle | L35: 0692631658 | M35: 0693111634 | N35: NUM W | O35: oui | Q35: non | U35: =IF(COUNTIFS(Contacts_Activation!D:D,D35,Contacts_Activation!N:N,"oui")>0,"oui","non") -> oui | V35: =IF(COUNTIFS(Travaux!C:C,D35,Travaux!X:X,"en_cours")>0,"travaux_en_cours",IF(COUNTIFS(Ventes!C:C,D35,Ventes!L:L,"signature")>0,"vente_signature",IF(COUNTIFS(Ventes!C:C,D35,Ventes!AD:AD,"oui")>0,"vente_bloquee",IF(COUNTIFS(Gestion_Locative!C:C,D35,Gestion_Locative!O:O,"incomplet")>0,"gestion_fragile","stable")))) -> vente_bloquee
A36: 3 | B36: Le Brulé | C36: LTS-003 | D36: LTS-003-002 | E36: AZALEES | F36: 111 Route des Azalées | G36: 4 | H36: 48 | I36: 58 | J36: IFIANTEPIA | K36: occupé en attente decision | L36: 0692229197 | O36: oui | Q36: non | U36: =IF(COUNTIFS(Contacts_Activation!D:D,D36,Contacts_Activation!N:N,"oui")>0,"oui","non") -> oui | V36: =IF(COUNTIFS(Travaux!C:C,D36,Travaux!X:X,"en_cours")>0,"travaux_en_cours",IF(COUNTIFS(Ventes!C:C,D36,Ventes!L:L,"signature")>0,"vente_signature",IF(COUNTIFS(Ventes!C:C,D36,Ventes!AD:AD,"oui")>0,"vente_bloquee",IF(COUNTIFS(Gestion_Locative!C:C,D36,Gestion_Locative!O:O,"incomplet")>0,"gestion_fragile","stable")))) -> vente_bloquee
A37: 3 | B37: Le Brulé | C37: LTS-003 | D37: LTS-003-003 | E37: AZALEES | F37: 107 ter Route des Azalées | G37: 4 | H37: 48 | I37: 58 | J37: THOMAS NÉE TURPIN | K37: Marie Micheline | L37: 0692587339 | O37: oui | Q37: non | U37: =IF(COUNTIFS(Contacts_Activation!D:D,D37,Contacts_Activation!N:N,"oui")>0,"oui","non") -> oui | V37: =IF(COUNTIFS(Travaux!C:C,D37,Travaux!X:X,"en_cours")>0,"travaux_en_cours",IF(COUNTIFS(Ventes!C:C,D37,Ventes!L:L,"signature")>0,"vente_signature",IF(COUNTIFS(Ventes!C:C,D37,Ventes!AD:AD,"oui")>0,"vente_bloquee",IF(COUNTIFS(Gestion_Locative!C:C,D37,Gestion_Locative!O:O,"incomplet")>0,"gestion_fragile","stable")))) -> vente_bloquee
A38: 3 | B38: Le Brulé | C38: LTS-003 | D38: LTS-003-004 | E38: AZALEES | F38: 107 bis Route des Azalées | G38: 4 | H38: 48 | I38: 58 | J38: POLEYA | K38: Joachim | L38: 0692743656 | O38: oui | Q38: non | U38: =IF(COUNTIFS(Contacts_Activation!D:D,D38,Contacts_Activation!N:N,"oui")>0,"oui","non") -> oui | V38: =IF(COUNTIFS(Travaux!C:C,D38,Travaux!X:X,"en_cours")>0,"travaux_en_cours",IF(COUNTIFS(Ventes!C:C,D38,Ventes!L:L,"signature")>0,"vente_signature",IF(COUNTIFS(Ventes!C:C,D38,Ventes!AD:AD,"oui")>0,"vente_bloquee",IF(COUNTIFS(Gestion_Locative!C:C,D38,Gestion_Locative!O:O,"incomplet")>0,"gestion_fragile","stable")))) -> vente_bloquee
A39: 2 | B39: Marcadet | C39: LTS-004 | D39: LTS-004-001 | E39: BARBADINES | F39: 65 Ruelle Marcadet | G39: 25 | H39: 57 | I39: 20 | J39: ABDALAH BEDANI | K39: Marie Thérèse | L39: 0692128814 | O39: oui | Q39: non | U39: =IF(COUNTIFS(Contacts_Activation!D:D,D39,Contacts_Activation!N:N,"oui")>0,"oui","non") -> oui | V39: =IF(COUNTIFS(Travaux!C:C,D39,Travaux!X:X,"en_cours")>0,"travaux_en_cours",IF(COUNTIFS(Ventes!C:C,D39,Ventes!L:L,"signature")>0,"vente_signature",IF(COUNTIFS(Ventes!C:C,D39,Ventes!AD:AD,"oui")>0,"vente_bloquee",IF(COUNTIFS(Gestion_Locative!C:C,D39,Gestion_Locative!O:O,"incomplet")>0,"gestion_fragile","stable")))) -> vente_bloquee
A40: 2 | B40: Marcadet | C40: LTS-004 | D40: LTS-004-002 | E40: BARBADINES | F40: 45 Ruelle Marcadet | G40: 25 | H40: 57 | I40: 20 | J40: MAILLOT | L40: 0692209721 | O40: oui | Q40: non | U40: =IF(COUNTIFS(Contacts_Activation!D:D,D40,Contacts_Activation!N:N,"oui")>0,"oui","non") -> oui | V40: =IF(COUNTIFS(Travaux!C:C,D40,Travaux!X:X,"en_cours")>0,"travaux_en_cours",IF(COUNTIFS(Ventes!C:C,D40,Ventes!L:L,"signature")>0,"vente_signature",IF(COUNTIFS(Ventes!C:C,D40,Ventes!AD:AD,"oui")>0,"vente_bloquee",IF(COUNTIFS(Gestion_Locative!C:C,D40,Gestion_Locative!O:O,"incomplet")>0,"gestion_fragile","stable")))) -> vente_bloquee
...

Sheet Logements
A1: secteur | B1: quartier | C1: code_lts | D1: code_acces | E1: adresse | F1: type de logement | G1: statut | H1: etat_general | I1: date_creation
A2: 1 | B2: Sainte Cloitlde | C2: LTS-001 | D2: LTS-001-001 | E2: 15 Bloc 20 Rue des Alamandas | F2: T4 | G2: occupé | H2: bon | I2: 1984
